Workbook

Sheet How It Works
B2: Ballpark: daily estimation game
B3: Five questions a day. Guess the number. Hit it out of the park.
B5: Days in this file | C5: =MAX('Daily Questions'!A2:A1501)
B6: Questions in this file | C6: =COUNTA('Daily Questions'!E2:E1501)
B7: First day | C7: ='Daily Questions'!B2
B8: Last day | C8: =MAX('Daily Questions'!B2:B1501)
B9: Repeated categories on any day | C9: =IF(MAX('Daily Questions'!L2:L1501)=1,"None. Every day has 5 different categories.","Check the red rows in Daily Questions")
B10: Daily format | C10: Questions 1 to 4 come from 10 rotating categories (Geography, Sports, Space and Science, Animals and Nature, Human Body, Buildings and Engineering, Movies Music and Games, History, Canada, Food and Everyday Life), never more than one per category in a day, and the same category is avoided on back-to-back days where possible. Questions are ordered easy to hard. Question 5 is always the Distance of the Day.
B11: How the game picks today's set | C11: The game counts days since the first date in this file. Day 1 = first date. If you launch later, just change the start date in the game, the order stays the same.
B12: Scoring | C12: See the Scoring tab. Closeness is a ratio (bigger divided by smaller), so guessing double the answer counts the same as guessing half. Within 10% clears the wall (400+ ft). Up to 3 swings per question in Classic mode; Easy mode is scored separately as right, close or wrong.
B13: Why there are no 'what year' questions | C13: Ratio scoring breaks on years. Guessing 1950 when the answer is 1969 is only 1% off, which would score 90. Every answer here is a positive amount where percent off is meaningful.
B14: Answers | C14: Rounded to a sensible precision. Use the rounded value shown as the 'exact' answer. Some facts (animal sizes, food stats, estimates) are commonly quoted averages, so the Source to Check column says where to confirm.
B15: Before launch | C15: Spot check the answers, especially the Hard ones, and mark the Verified column. Fix anything flagged before that day goes live. Days 90 to 300 (Jan 2 to Jul 31, 2027) were added in Oct 2026 and are marked in the Notes column.
B16: Adding more days | C16: Add new rows at the bottom with the next Day numbers and dates, following the same 5-per-day pattern. The Category Repeats column turns red if a day has two questions from the same category.

Sheet Scoring
A1: Hit | B1: Guess within | C1: Points | D1: Feet | F1: Try it
A2: Out of the park | B2: 10% | C2: 89 to 100 | D2: 400 to 450 | F2: Real answer | G2: 3359
A3: Deep to the wall | B3: 25% | C3: 67 to 88 | D3: 300 to 400 | F3: Your guess | G3: 3000
A4: Solid hit | B4: 50% | C4: 45 to 66 | D4: 200 to 300 | F4: How far off (ratio) | G4: =IFERROR(MAX(G2,G3)/MIN(G2,G3),"")
A5: In play | B5: 2x | C5: 23 to 44 | D5: 100 to 200 | F5: Hit | G5: =IF(G4="","",IF(G4<=1.1,"Out of the park",IF(G4<=1.25,"Deep to the wall",IF(G4<=1.5,"Solid hit",IF(G4<=2,"In play",IF(G4<=4,"Caught","Swing and a miss"))))))
A6: Caught | B6: 4x | C6: 1 to 22 | D6: under 100
A7: Swing and a miss | B7: more than 4x | C7: 0 | D7: 0 | F7: Change the blue cells to test. Each extra swing is worth 15% less (then 30%), and a hint costs 15%.
F9: Max possible per day | G9: 2,250 ft (450 per question)

Sheet Daily Questions
A1: Day | B1: Date | C1: Q# | D1: Category | E1: Question | F1: Answer | G1: Unit | H1: Difficulty | I1: Source to Check | J1: Verified? | K1: Notes | L1: Category Repeats (must be 1)
A2: 1 | B2: 46300 | C2: 1 | D2: Buildings and Engineering | E2: How tall is the Hoover Dam? | F2: 221 | G2: metres | H2: Medium | I2: US Bureau of Reclamation | L2: =COUNTIFS($A$2:$A$1501,A2,$D$2:$D$1501,D2)
A3: 1 | B3: 46300 | C3: 2 | D3: Movies, Music and Games | E3: How long is The Godfather? | F3: 175 | G3: minutes | H3: Medium | I3: IMDb | L3: =COUNTIFS($A$2:$A$1501,A3,$D$2:$D$1501,D3)
A4: 1 | B4: 46300 | C4: 3 | D4: Geography | E4: How tall is Aconcagua, the highest mountain in South America? | F4: 6961 | G4: metres | H4: Hard | I4: Britannica / national survey agencies | L4: =COUNTIFS($A$2:$A$1501,A4,$D$2:$D$1501,D4)
A5: 1 | B5: 46300 | C5: 4 | D5: Sports | E5: How many consecutive games did Cal Ripken Jr. play? | F5: 2632 | G5: games | H5: Hard | I5: MLB.com | L5: =COUNTIFS($A$2:$A$1501,A5,$D$2:$D$1501,D5)
A6: 1 | B6: 46300 | C6: 5 | D6: Distance of the Day | E6: How far is it in a straight line from Iqaluit to New York? | F6: 2590 | G6: km | H6: Medium | I6: Computed great-circle distance (city centre to city centre) | L6: =COUNTIFS($A$2:$A$1501,A6,$D$2:$D$1501,D6)
A7: 2 | B7: 46301 | C7: 1 | D7: Animals and Nature | E7: How many eggs does a modern laying hen produce in a year? | F7: 300 | G7: eggs | H7: Medium | I7: Britannica / National Geographic / Guinness World Records | L7: =COUNTIFS($A$2:$A$1501,A7,$D$2:$D$1501,D7)
A8: 2 | B8: 46301 | C8: 2 | D8: Canada | E8: How many litres of maple sap does it take to make 1 litre of maple syrup? | F8: 40 | G8: litres | H8: Medium | I8: Natural Resources Canada / Statistics Canada / Parks Canada | L8: =COUNTIFS($A$2:$A$1501,A8,$D$2:$D$1501,D8)
A9: 2 | B9: 46301 | C9: 3 | D9: Space and Science | E9: How many centimetres does the Moon drift away from Earth each year? | F9: 3.8 | G9: cm | H9: Hard | I9: NASA | L9: =COUNTIFS($A$2:$A$1501,A9,$D$2:$D$1501,D9)
A10: 2 | B10: 46301 | C10: 4 | D10: History | E10: How long was the Oregon Trail? | F10: 3490 | G10: km | H10: Hard | I10: US National Park Service | L10: =COUNTIFS($A$2:$A$1501,A10,$D$2:$D$1501,D10)
A11: 2 | B11: 46301 | C11: 5 | D11: Distance of the Day | E11: How far is it in a straight line from Karachi to Singapore? | F11: 4740 | G11: km | H11: Medium | I11: Computed great-circle distance (city centre to city centre) | L11: =COUNTIFS($A$2:$A$1501,A11,$D$2:$D$1501,D11)
A12: 3 | B12: 46302 | C12: 1 | D12: Buildings and Engineering | E12: How tall was the Saturn V rocket that launched Apollo 11? | F12: 111 | G12: metres | H12: Medium | I12: NASA | L12: =COUNTIFS($A$2:$A$1501,A12,$D$2:$D$1501,D12)
A13: 3 | B13: 46302 | C13: 2 | D13: Sports | E13: How many Stanley Cups have the Montreal Canadiens won? | F13: 24 | G13: Stanley Cups | H13: Medium | I13: NHL Records | L13: =COUNTIFS($A$2:$A$1501,A13,$D$2:$D$1501,D13)
... A177: 36 | B177: 46335 | C177: 1 | D177: Food and Everyday Life | E177: How many grams of sugar are in a 355 mL can of Coca-Cola? | F177: 39 | G177: grams | H177: Easy | I177: Coca-Cola | L177: =COUNTIFS($A$2:$A$1501,A177,$D$2:$D$1501,D177)
A178: 36 | B178: 46335 | C178: 2 | D178: Space and Science | E178: What is the atomic number of uranium? | F178: 92 | H178: Medium | I178: IUPAC | L178: =COUNTIFS($A$2:$A$1501,A178,$D$2:$D$1501,D178)
A179: 36 | B179: 46335 | C179: 3 | D179: Human Body | E179: How long is the adult spinal cord? | F179: 45 | G179: cm | H179: Hard | I179: Cleveland Clinic / NIH / Guinness World Records | L179: =COUNTIFS($A$2:$A$1501,A179,$D$2:$D$1501,D179)
A180: 36 | B180: 46335 | C180: 4 | D180: Animals and Nature | E180: How many times per second does a honeybee beat its wings? | F180: 230 | G180: beats | H180: Hard | I180: Britannica / National Geographic / Guinness World Records | L180: =COUNTIFS($A$2:$A$1501,A180,$D$2:$D$1501,D180)
A181: 36 | B181: 46335 | C181: 5 | D181: Distance of the Day | E181: How far is it in a straight line from Miami to Nairobi? | F181: 12760 | G181: km | H181: Hard | I181: Computed great-circle distance (city centre to city centre) | L181: =COUNTIFS($A$2:$A$1501,A181,$D$2:$D$1501,D181)
A182: 37 | B182: 46336 | C182: 1 | D182: Movies, Music and Games | E182: How many sonnets did Shakespeare write? | F182: 154 | G182: sonnets | H182: Medium | I182: IMDb / official records / Guinness World Records | L182: =COUNTIFS($A$2:$A$1501,A182,$D$2:$D$1501,D182)
A183: 37 | B183: 46336 | C183: 2 | D183: Geography | E183: How long is the Great Wall of China, counting all its branches? | F183: 21196 | G183: km | H183: Hard | I183: China State Administration of Cultural Heritage 2012 | L183: =COUNTIFS($A$2:$A$1501,A183,$D$2:$D$1501,D183)
A184: 37 | B184: 46336 | C184: 3 | D184: Buildings and Engineering | E184: How long is the Gotthard Base Tunnel in Switzerland, the world's longest rail tunnel? | F184: 57 | G184: km | H184: Hard | I184: SBB | L184: =COUNTIFS($A$2:$A$1501,A184,$D$2:$D$1501,D184)
A185: 37 | B185: 46336 | C185: 4 | D185: Sports | E185: How many hits did Ichiro Suzuki get in his record 2004 season? | F185: 262 | G185: hits | H185: Hard | I185: MLB.com | L185: =COUNTIFS($A$2:$A$1501,A185,$D$2:$D$1501,D185)
A186: 37 | B186: 46336 | C186: 5 | D186: Distance of the Day | E186: How far is it in a straight line from Ottawa to Buenos Aires? | F186: 9070 | G186: km | H186: Hard | I186: Computed great-circle distance (city centre to city centre) | L186: =COUNTIFS($A$2:$A$1501,A186,$D$2:$D$1501,D186)
A187: 38 | B187: 46337 | C187: 1 | D187: Space and Science | E187: How many elements are on the periodic table? | F187: 118 | G187: elements | H187: Easy | I187: IUPAC | L187: =COUNTIFS($A$2:$A$1501,A187,$D$2:$D$1501,D187)
A188: 38 | B188: 46337 | C188: 2 | D188: History | E188: How many years did Queen Elizabeth II reign? | F188: 70 | G188: years | H188: Easy | I188: Britannica / national archives | L188: =COUNTIFS($A$2:$A$1501,A188,$D$2:$D$1501,D188)
A189: 38 | B189: 46337 | C189: 3 | D189: Canada | E189: How many steps are in the CN Tower's stairwell? | F189: 1776 | G189: steps | H189: Hard | I189: CN Tower | L189: =COUNTIFS($A$2:$A$1501,A189,$D$2:$D$1501,D189)
A190: 38 | B190: 46337 | C190: 4 | D190: Human Body | E190: How many sweat glands does the average person have? | F190: 3000000 | G190: sweat glands | H190: Hard | I190: Cleveland Clinic / NIH / Guinness World Records | L190: =COUNTIFS($A$2:$A$1501,A190,$D$2:$D$1501,D190)
... A216: 43 | B216: 46342 | C216: 5 | D216: Distance of the Day | E216: How far is it in a straight line from Whitehorse to Karachi? | F216: 10290 | G216: km | H216: Hard | I216: Computed great-circle distance (city centre to city centre) | L216: =COUNTIFS($A$2:$A$1501,A216,$D$2:$D$1501,D216)
A217: 44 | B217: 46343 | C217: 1 | D217: Space and Science | E217: What is the atomic number of gold? | F217: 79 | H217: Medium | I217: IUPAC | L217: =COUNTIFS($A$2:$A$1501,A217,$D$2:$D$1501,D217)
A218: 44 | B218: 46343 | C218: 2 | D218: Canada | E218: What percentage of the world's maple syrup comes from Quebec? | F218: 72 | G218: % | H218: Medium | I218: Quebec Maple Syrup Producers | L218: =COUNTIFS($A$2:$A$1501,A218,$D$2:$D$1501,D218)
A219: 44 | B219: 46343 | C219: 3 | D219: Food and Everyday Life | E219: How much caffeine is in a single shot of espresso? | F219: 63 | G219: mg | H219: Medium | I219: USDA | L219: =COUNTIFS($A$2:$A$1501,A219,$D$2:$D$1501,D219)
A220: 44 | B220: 46343 | C220: 4 | D220: Animals and Nature | E220: What is the hottest air temperature ever recorded on Earth? | F220: 56.7 | G220: °C | H220: Medium | I220: World Meteorological Organization | L220: =COUNTIFS($A$2:$A$1501,A220,$D$2:$D$1501,D220)
A221: 44 | B221: 46343 | C221: 5 | D221: Distance of the Day | E221: How far is it in a straight line from Lahore to Seoul? | F221: 4800 | G221: km | H221: Medium | I221: Computed great-circle distance (city centre to city centre) | L221: =COUNTIFS($A$2:$A$1501,A221,$D$2:$D$1501,D221)
A222: 45 | B222: 46344 | C222: 1 | D222: Geography | E222: How tall is Mount Fuji? | F222: 3776 | G222: metres | H222: Medium | I222: Britannica / national survey agencies | L222: =COUNTIFS($A$2:$A$1501,A222,$D$2:$D$1501,D222)
A223: 45 | B223: 46344 | C223: 2 | D223: Movies, Music and Games | E223: How long is Shrek? | F223: 90 | G223: minutes | H223: Medium | I223: IMDb | L223: =COUNTIFS($A$2:$A$1501,A223,$D$2:$D$1501,D223)
A224: 45 | B224: 46344 | C224: 3 | D224: Buildings and Engineering | E224: How tall is the Shanghai Tower? | F224: 632 | G224: metres | H224: Hard | I224: CTBUH | L224: =COUNTIFS($A$2:$A$1501,A224,$D$2:$D$1501,D224)
A225: 45 | B225: 46344 | C225: 4 | D225: Sports | E225: How many rushing yards did Eric Dickerson gain in his record 1984 season? | F225: 2105 | G225: yards | H225: Hard | I225: NFL.com | L225: =COUNTIFS($A$2:$A$1501,A225,$D$2:$D$1501,D225)
A226: 45 | B226: 46344 | C226: 5 | D226: Distance of the Day | E226: How far is it in a straight line from Halifax to Seoul? | F226: 10810 | G226: km | H226: Hard | I226: Computed great-circle distance (city centre to city centre) | L226: =COUNTIFS($A$2:$A$1501,A226,$D$2:$D$1501,D226)
A227: 46 | B227: 46345 | C227: 1 | D227: Space and Science | E227: What is the atomic number of silver? | F227: 47 | H227: Medium | I227: IUPAC | L227: =COUNTIFS($A$2:$A$1501,A227,$D$2:$D$1501,D227)
A228: 46 | B228: 46345 | C228: 2 | D228: Food and Everyday Life | E228: How many teaspoons are in one cup? | F228: 48 | G228: teaspoons | H228: Medium | I228: Food industry bodies / USDA / Water Footprint Network | L228: =COUNTIFS($A$2:$A$1501,A228,$D$2:$D$1501,D228)
...

Sheet Category Mix
A1: Category | B1: Questions | C1: Easy | D1: Medium | E1: Hard
A2: Animals and Nature | B2: =COUNTIF('Daily Questions'!$D$2:$D$1501,A2) | C2: =COUNTIFS('Daily Questions'!$D$2:$D$1501,A2,'Daily Questions'!$H$2:$H$1501,"Easy") | D2: =COUNTIFS('Daily Questions'!$D$2:$D$1501,A2,'Daily Questions'!$H$2:$H$1501,"Medium") | E2: =COUNTIFS('Daily Questions'!$D$2:$D$1501,A2,'Daily Questions'!$H$2:$H$1501,"Hard")
A3: Buildings and Engineering | B3: =COUNTIF('Daily Questions'!$D$2:$D$1501,A3) | C3: =COUNTIFS('Daily Questions'!$D$2:$D$1501,A3,'Daily Questions'!$H$2:$H$1501,"Easy") | D3: =COUNTIFS('Daily Questions'!$D$2:$D$1501,A3,'Daily Questions'!$H$2:$H$1501,"Medium") | E3: =COUNTIFS('Daily Questions'!$D$2:$D$1501,A3,'Daily Questions'!$H$2:$H$1501,"Hard")
A4: Canada | B4: =COUNTIF('Daily Questions'!$D$2:$D$1501,A4) | C4: =COUNTIFS('Daily Questions'!$D$2:$D$1501,A4,'Daily Questions'!$H$2:$H$1501,"Easy") | D4: =COUNTIFS('Daily Questions'!$D$2:$D$1501,A4,'Daily Questions'!$H$2:$H$1501,"Medium") | E4: =COUNTIFS('Daily Questions'!$D$2:$D$1501,A4,'Daily Questions'!$H$2:$H$1501,"Hard")
A5: Distance of the Day | B5: =COUNTIF('Daily Questions'!$D$2:$D$1501,A5) | C5: =COUNTIFS('Daily Questions'!$D$2:$D$1501,A5,'Daily Questions'!$H$2:$H$1501,"Easy") | D5: =COUNTIFS('Daily Questions'!$D$2:$D$1501,A5,'Daily Questions'!$H$2:$H$1501,"Medium") | E5: =COUNTIFS('Daily Questions'!$D$2:$D$1501,A5,'Daily Questions'!$H$2:$H$1501,"Hard")
A6: Food and Everyday Life | B6: =COUNTIF('Daily Questions'!$D$2:$D$1501,A6) | C6: =COUNTIFS('Daily Questions'!$D$2:$D$1501,A6,'Daily Questions'!$H$2:$H$1501,"Easy") | D6: =COUNTIFS('Daily Questions'!$D$2:$D$1501,A6,'Daily Questions'!$H$2:$H$1501,"Medium") | E6: =COUNTIFS('Daily Questions'!$D$2:$D$1501,A6,'Daily Questions'!$H$2:$H$1501,"Hard")
A7: Geography | B7: =COUNTIF('Daily Questions'!$D$2:$D$1501,A7) | C7: =COUNTIFS('Daily Questions'!$D$2:$D$1501,A7,'Daily Questions'!$H$2:$H$1501,"Easy") | D7: =COUNTIFS('Daily Questions'!$D$2:$D$1501,A7,'Daily Questions'!$H$2:$H$1501,"Medium") | E7: =COUNTIFS('Daily Questions'!$D$2:$D$1501,A7,'Daily Questions'!$H$2:$H$1501,"Hard")
A8: History | B8: =COUNTIF('Daily Questions'!$D$2:$D$1501,A8) | C8: =COUNTIFS('Daily Questions'!$D$2:$D$1501,A8,'Daily Questions'!$H$2:$H$1501,"Easy") | D8: =COUNTIFS('Daily Questions'!$D$2:$D$1501,A8,'Daily Questions'!$H$2:$H$1501,"Medium") | E8: =COUNTIFS('Daily Questions'!$D$2:$D$1501,A8,'Daily Questions'!$H$2:$H$1501,"Hard")
A9: Human Body | B9: =COUNTIF('Daily Questions'!$D$2:$D$1501,A9) | C9: =COUNTIFS('Daily Questions'!$D$2:$D$1501,A9,'Daily Questions'!$H$2:$H$1501,"Easy") | D9: =COUNTIFS('Daily Questions'!$D$2:$D$1501,A9,'Daily Questions'!$H$2:$H$1501,"Medium") | E9: =COUNTIFS('Daily Questions'!$D$2:$D$1501,A9,'Daily Questions'!$H$2:$H$1501,"Hard")
A10: Movies, Music and Games | B10: =COUNTIF('Daily Questions'!$D$2:$D$1501,A10) | C10: =COUNTIFS('Daily Questions'!$D$2:$D$1501,A10,'Daily Questions'!$H$2:$H$1501,"Easy") | D10: =COUNTIFS('Daily Questions'!$D$2:$D$1501,A10,'Daily Questions'!$H$2:$H$1501,"Medium") | E10: =COUNTIFS('Daily Questions'!$D$2:$D$1501,A10,'Daily Questions'!$H$2:$H$1501,"Hard")
A11: Space and Science | B11: =COUNTIF('Daily Questions'!$D$2:$D$1501,A11) | C11: =COUNTIFS('Daily Questions'!$D$2:$D$1501,A11,'Daily Questions'!$H$2:$H$1501,"Easy") | D11: =COUNTIFS('Daily Questions'!$D$2:$D$1501,A11,'Daily Questions'!$H$2:$H$1501,"Medium") | E11: =COUNTIFS('Daily Questions'!$D$2:$D$1501,A11,'Daily Questions'!$H$2:$H$1501,"Hard")
A12: Sports | B12: =COUNTIF('Daily Questions'!$D$2:$D$1501,A12) | C12: =COUNTIFS('Daily Questions'!$D$2:$D$1501,A12,'Daily Questions'!$H$2:$H$1501,"Easy") | D12: =COUNTIFS('Daily Questions'!$D$2:$D$1501,A12,'Daily Questions'!$H$2:$H$1501,"Medium") | E12: =COUNTIFS('Daily Questions'!$D$2:$D$1501,A12,'Daily Questions'!$H$2:$H$1501,"Hard")
A13: Total | B13: =SUM(B2:B12) | C13: =SUM(C2:C12) | D13: =SUM(D2:D12) | E13: =SUM(E2:E12)

Sheet Reserve
A1: Category | B1: Question | C1: Answer | D1: Unit | E1: Difficulty | F1: Source to Check | G1: Notes
A2: Animals and Nature | B2: How many legs does a spider have? | C2: 8 | D2: legs | E2: Easy | F2: National Geographic | G2: Spare question, not scheduled yet
A3: Human Body | B3: How many litres of air can adult lungs hold in total? | C3: 6 | D3: litres | E3: Medium | F3: American Lung Association | G3: Spare question, not scheduled yet
A4: Buildings and Engineering | B4: How tall is The Motherland Calls statue in Volgograd? | C4: 85 | D4: metres | E4: Hard | F4: Britannica | G4: Spare question, not scheduled yet
A5: Buildings and Engineering | B5: How long is the Hollywood Sign? | C5: 107 | D5: metres | E5: Hard | F5: Hollywood Sign Trust | G5: Spare question, not scheduled yet
A6: Canada | B6: How much snow does Montreal get in a typical year? | C6: 210 | D6: cm | E6: Hard | F6: Environment and Climate Change Canada | G6: Spare question, not scheduled yet
A7: Food and Everyday Life | B7: How many minutes does dried spaghetti usually take to cook? | C7: 10 | D7: minutes | E7: Easy | F7: Barilla | G7: Spare question, not scheduled yet
A8: Food and Everyday Life | B8: How many millilitres are in a tablespoon? | C8: 15 | D8: mL | E8: Medium | F8: Health Canada | G8: Spare question, not scheduled yet
A9: Geography | B9: How many countries share a land border with Russia? | C9: 14 | D9: countries | E9: Medium | F9: CIA World Factbook | G9: Spare question, not scheduled yet
A10: Geography | B10: How high above sea level is Lake Titicaca? | C10: 3812 | D10: metres | E10: Hard | F10: Britannica | G10: Spare question, not scheduled yet
A11: History | B11: How deep is the wreck of the Titanic? | C11: 3800 | D11: metres | E11: Medium | F11: NOAA | G11: Spare question, not scheduled yet
A12: Movies, Music and Games | B12: How long is The Matrix? | C12: 136 | D12: minutes | E12: Medium | F12: IMDb | G12: Spare question, not scheduled yet
A13: Movies, Music and Games | B13: How tall is an Oscar statuette? | C13: 34 | D13: cm | E13: Medium | F13: Academy of Motion Picture Arts and Sciences | G13: Spare question, not scheduled yet
A14: Space and Science | B14: What is the atomic number of oxygen? | C14: 8 | E14: Easy | F14: IUPAC periodic table | G14: Spare question, not scheduled yet
A15: Sports | B15: How long is one lap of the Indianapolis Motor Speedway? | C15: 2.5 | D15: miles | E15: Hard | F15: Indianapolis Motor Speedway | G15: Spare question, not scheduled yet
A16: Sports | B16: How many assists did John Stockton record in his NBA career? | C16: 15806 | D16: assists | E16: Hard | F16: NBA.com | G16: Spare question, not scheduled yet
